Workbook

Sheet Sell CTW
J1: =SUM(J3:J3219) -> 3296 | K1: =SUM(K3:K3219) -> 2681168 | L1: =SUM(L3:L3219) -> 570532.5 | M1: =SUM(M3:M3219) -> 2089594 | N1: =SUM(N3:N3219) -> 2089934
A2: Month | B2: วันที่ | C2: BA | D2: เลขที่คำสั่งซื้อ | E2: เลขที่ใบเสร็จ | F2: รายการ | G2: Barcode | H2: Grand | I2: Size | J2: จำนวน | K2: ราคา | L2: ส่วนลด | M2: รวม | N2: ยอดชำระ | O2: ช่องทางชำระ | P2: Date | Q2: Time | R2: UID | S2: หมายเหตุ | T2: Nation
A3: Nov-25 | B3: 45982 | C3: Pure, Jom | D3: 1763665444492552897 | E3: 202500000000030 | F3: Make Way50 ml. | G3: {=IF(F3<>"",INDEX(tb_MainDatabase[Barcode],MATCH(F3,tb_MainDatabase[Link],0)),"")} -> 8857128012020 | H3: {=IF(F3<>"",INDEX(tb_MainDatabase[Grand],MATCH(F3,tb_MainDatabase[Link],0)),"")} -> EDP | I3: {=IF(F3<>"",INDEX(tb_MainDatabase[Size],MATCH(F3,tb_MainDatabase[Link],0)),"")} -> 50 ml. | J3: 1 | K3: {=IF(F3<>"",INDEX(tb_MainDatabase[ราคา],MATCH(F3,tb_MainDatabase[Link],0)),"")*J3} -> 1890 | L3: 500 | M3: =K3-(L3*J3) -> 1390 | N3: =SUMIF($D$3:D3219,R3,$M$3:M3219) -> 10340 | O3: K Shop Credit Card | P3: 45982 | Q3: 0.44930556 | R3: =IF(COUNTIF(D$3:D3, D3)>1, 0, D3) -> 1763665444492552897
A4: Nov-25 | B4: 45982 | C4: Pure, Jom | D4: 1763665444492552897 | E4: 202500000000030 | F4: Make Way30 ml. | G4: {=IF(F4<>"",INDEX(tb_MainDatabase[Barcode],MATCH(F4,tb_MainDatabase[Link],0)),"")} -> 8857128012024 | H4: {=IF(F4<>"",INDEX(tb_MainDatabase[Grand],MATCH(F4,tb_MainDatabase[Link],0)),"")} -> EDP | I4: {=IF(F4<>"",INDEX(tb_MainDatabase[Size],MATCH(F4,tb_MainDatabase[Link],0)),"")} -> 30 ml. | J4: 1 | K4: {=IF(F4<>"",INDEX(tb_MainDatabase[ราคา],MATCH(F4,tb_MainDatabase[Link],0)),"")*J4} -> 1290 | L4: 300 | M4: =K4-(L4*J4) -> 990 | N4: =SUMIF($D$3:D3220,R4,$M$3:M3220) -> 0 | R4: =IF(COUNTIF(D$3:D4, D4)>1, 0, D4) -> 0
A5: Nov-25 | B5: 45982 | C5: Pure, Jom | D5: 1763665444492552897 | E5: 202500000000030 | F5: Sparkling Mandarin50 ml. | G5: {=IF(F5<>"",INDEX(tb_MainDatabase[Barcode],MATCH(F5,tb_MainDatabase[Link],0)),"")} -> 8857128011713 | H5: {=IF(F5<>"",INDEX(tb_MainDatabase[Grand],MATCH(F5,tb_MainDatabase[Link],0)),"")} -> EDP+ | I5: {=IF(F5<>"",INDEX(tb_MainDatabase[Size],MATCH(F5,tb_MainDatabase[Link],0)),"")} -> 50 ml. | J5: 2 | K5: {=IF(F5<>"",INDEX(tb_MainDatabase[ราคา],MATCH(F5,tb_MainDatabase[Link],0)),"")*J5} -> 5780 | L5: 600 | M5: =K5-(L5*J5) -> 4580 | N5: =SUMIF($D$3:D3221,R5,$M$3:M3221) -> 0 | R5: =IF(COUNTIF(D$3:D5, D5)>1, 0, D5) -> 0
A6: Nov-25 | B6: 45982 | C6: Pure, Jom | D6: 1763665444492552897 | E6: 202500000000030 | F6: Sparkling Mandarin30 ml. | G6: {=IF(F6<>"",INDEX(tb_MainDatabase[Barcode],MATCH(F6,tb_MainDatabase[Link],0)),"")} -> 8857128012010 | H6: {=IF(F6<>"",INDEX(tb_MainDatabase[Grand],MATCH(F6,tb_MainDatabase[Link],0)),"")} -> EDP+ | I6: {=IF(F6<>"",INDEX(tb_MainDatabase[Size],MATCH(F6,tb_MainDatabase[Link],0)),"")} -> 30 ml. | J6: 2 | K6: {=IF(F6<>"",INDEX(tb_MainDatabase[ราคา],MATCH(F6,tb_MainDatabase[Link],0)),"")*J6} -> 3780 | L6: 200 | M6: =K6-(L6*J6) -> 3380 | N6: =SUMIF($D$3:D3222,R6,$M$3:M3222) -> 0 | R6: =IF(COUNTIF(D$3:D6, D6)>1, 0, D6) -> 0
A7: Nov-25 | B7: 45982 | C7: Pure, Jom | D7: 1763665444492552897 | E7: 202500000000030 | F7: Tumbler CYOC (Dark Blue)Dark Blue | G7: {=IF(F7<>"",INDEX(tb_MainDatabase[Barcode],MATCH(F7,tb_MainDatabase[Link],0)),"")} -> 8857128012131 | H7: {=IF(F7<>"",INDEX(tb_MainDatabase[Grand],MATCH(F7,tb_MainDatabase[Link],0)),"")} -> Tumbler | I7: {=IF(F7<>"",INDEX(tb_MainDatabase[Size],MATCH(F7,tb_MainDatabase[Link],0)),"")} -> Dark Blue | J7: 1 | K7: {=IF(F7<>"",INDEX(tb_MainDatabase[ราคา],MATCH(F7,tb_MainDatabase[Link],0)),"")*J7} -> 0 | M7: =K7-(L7*J7) -> 0 | N7: =SUMIF($D$3:D3223,R7,$M$3:M3223) -> 0 | R7: =IF(COUNTIF(D$3:D7, D7)>1, 0, D7) -> 0
A8: Nov-25 | B8: 45982 | C8: Pure, Jom | D8: 1763665444492552897 | E8: 202500000000030 | F8: Cloth BAG CYOCSize M | G8: {=IF(F8<>"",INDEX(tb_MainDatabase[Barcode],MATCH(F8,tb_MainDatabase[Link],0)),"")} -> 8857128012132 | H8: {=IF(F8<>"",INDEX(tb_MainDatabase[Grand],MATCH(F8,tb_MainDatabase[Link],0)),"")} -> Cloth | I8: {=IF(F8<>"",INDEX(tb_MainDatabase[Size],MATCH(F8,tb_MainDatabase[Link],0)),"")} -> Size M | J8: 1 | K8: {=IF(F8<>"",INDEX(tb_MainDatabase[ราคา],MATCH(F8,tb_MainDatabase[Link],0)),"")*J8} -> 0 | M8: =K8-(L8*J8) -> 0 | N8: =SUMIF($D$3:D3224,R8,$M$3:M3224) -> 0 | R8: =IF(COUNTIF(D$3:D8, D8)>1, 0, D8) -> 0
A9: Nov-25 | B9: 45982 | C9: Pure, Jom | D9: 1763665444492552897 | E9: 202500000000030 | F9: Buoyant4 ml. | G9: {=IF(F9<>"",INDEX(tb_MainDatabase[Barcode],MATCH(F9,tb_MainDatabase[Link],0)),"")} -> 8857128012078 | H9: {=IF(F9<>"",INDEX(tb_MainDatabase[Grand],MATCH(F9,tb_MainDatabase[Link],0)),"")} -> EDP | I9: {=IF(F9<>"",INDEX(tb_MainDatabase[Size],MATCH(F9,tb_MainDatabase[Link],0)),"")} -> 4 ml. | J9: 1 | K9: {=IF(F9<>"",INDEX(tb_MainDatabase[ราคา],MATCH(F9,tb_MainDatabase[Link],0)),"")*J9} -> 179 | L9: 179 | M9: =K9-(L9*J9) -> 0 | N9: =SUMIF($D$3:D3225,R9,$M$3:M3225) -> 0 | R9: =IF(COUNTIF(D$3:D9, D9)>1, 0, D9) -> 0
A10: Nov-25 | B10: 45982 | C10: Pure, Jom | D10: 1763665444492552897 | E10: 202500000000030 | F10: Senorita4 ml. | G10: {=IF(F10<>"",INDEX(tb_MainDatabase[Barcode],MATCH(F10,tb_MainDatabase[Link],0)),"")} -> 8857128012040 | H10: {=IF(F10<>"",INDEX(tb_MainDatabase[Grand],MATCH(F10,tb_MainDatabase[Link],0)),"")} -> EDP | I10: {=IF(F10<>"",INDEX(tb_MainDatabase[Size],MATCH(F10,tb_MainDatabase[Link],0)),"")} -> 4 ml. | J10: 1 | K10: {=IF(F10<>"",INDEX(tb_MainDatabase[ราคา],MATCH(F10,tb_MainDatabase[Link],0)),"")*J10} -> 179 | L10: 179 | M10: =K10-(L10*J10) -> 0 | N10: =SUMIF($D$3:D3226,R10,$M$3:M3226) -> 0 | R10: =IF(COUNTIF(D$3:D10, D10)>1, 0, D10) -> 0
A11: Nov-25 | B11: 45982 | C11: Pure, Jom | D11: 1763696917196248249 | E11: 202500000000031 | F11: La Belle50 ml. | G11: {=IF(F11<>"",INDEX(tb_MainDatabase[Barcode],MATCH(F11,tb_MainDatabase[Link],0)),"")} -> 8857128011058 | H11: {=IF(F11<>"",INDEX(tb_MainDatabase[Grand],MATCH(F11,tb_MainDatabase[Link],0)),"")} -> EDP | I11: {=IF(F11<>"",INDEX(tb_MainDatabase[Size],MATCH(F11,tb_MainDatabase[Link],0)),"")} -> 50 ml. | J11: 2 | K11: {=IF(F11<>"",INDEX(tb_MainDatabase[ราคา],MATCH(F11,tb_MainDatabase[Link],0)),"")*J11} -> 3780 | L11: 500 | M11: =K11-(L11*J11) -> 2780 | N11: =SUMIF($D$3:D3227,R11,$M$3:M3227) -> 8340 | O11: K Shop Credit Card | P11: 45982 | Q11: 0.45833333 | R11: =IF(COUNTIF(D$3:D11, D11)>1, 0, D11) -> 1763696917196248249
A12: Nov-25 | B12: 45982 | C12: Pure, Jom | D12: 1763696917196248249 | E12: 202500000000031 | F12: Senorita50 ml. | G12: {=IF(F12<>"",INDEX(tb_MainDatabase[Barcode],MATCH(F12,tb_MainDatabase[Link],0)),"")} -> 8857128011171 | H12: {=IF(F12<>"",INDEX(tb_MainDatabase[Grand],MATCH(F12,tb_MainDatabase[Link],0)),"")} -> EDP | I12: {=IF(F12<>"",INDEX(tb_MainDatabase[Size],MATCH(F12,tb_MainDatabase[Link],0)),"")} -> 50 ml. | J12: 2 | K12: {=IF(F12<>"",INDEX(tb_MainDatabase[ราคา],MATCH(F12,tb_MainDatabase[Link],0)),"")*J12} -> 3780 | L12: 500 | M12: =K12-(L12*J12) -> 2780 | N12: =SUMIF($D$3:D3228,R12,$M$3:M3228) -> 0 | R12: =IF(COUNTIF(D$3:D12, D12)>1, 0, D12) -> 0
A13: Nov-25 | B13: 45982 | C13: Pure, Jom | D13: 1763696917196248249 | E13: 202500000000031 | F13: Voyage50 ml. | G13: {=IF(F13<>"",INDEX(tb_MainDatabase[Barcode],MATCH(F13,tb_MainDatabase[Link],0)),"")} -> 8857128012019 | H13: {=IF(F13<>"",INDEX(tb_MainDatabase[Grand],MATCH(F13,tb_MainDatabase[Link],0)),"")} -> EDP | I13: {=IF(F13<>"",INDEX(tb_MainDatabase[Size],MATCH(F13,tb_MainDatabase[Link],0)),"")} -> 50 ml. | J13: 2 | K13: {=IF(F13<>"",INDEX(tb_MainDatabase[ราคา],MATCH(F13,tb_MainDatabase[Link],0)),"")*J13} -> 3780 | L13: 500 | M13: =K13-(L13*J13) -> 2780 | N13: =SUMIF($D$3:D3229,R13,$M$3:M3229) -> 0 | R13: =IF(COUNTIF(D$3:D13, D13)>1, 0, D13) -> 0
A14: Nov-25 | B14: 45982 | C14: Pure, Jom | D14: 1763696917196248249 | E14: 202500000000031 | F14: Senorita4 ml. | G14: {=IF(F14<>"",INDEX(tb_MainDatabase[Barcode],MATCH(F14,tb_MainDatabase[Link],0)),"")} -> 8857128012040 | H14: {=IF(F14<>"",INDEX(tb_MainDatabase[Grand],MATCH(F14,tb_MainDatabase[Link],0)),"")} -> EDP | I14: {=IF(F14<>"",INDEX(tb_MainDatabase[Size],MATCH(F14,tb_MainDatabase[Link],0)),"")} -> 4 ml. | J14: 1 | K14: {=IF(F14<>"",INDEX(tb_MainDatabase[ราคา],MATCH(F14,tb_MainDatabase[Link],0)),"")*J14} -> 179 | L14: 179 | M14: =K14-(L14*J14) -> 0 | N14: =SUMIF($D$3:D3230,R14,$M$3:M3230) -> 0 | R14: =IF(COUNTIF(D$3:D14, D14)>1, 0, D14) -> 0
A15: Nov-25 | B15: 45982 | C15: Pure, Jom | D15: 1763696917196248249 | E15: 202500000000031 | F15: Buoyant4 ml. | G15: {=IF(F15<>"",INDEX(tb_MainDatabase[Barcode],MATCH(F15,tb_MainDatabase[Link],0)),"")} -> 8857128012078 | H15: {=IF(F15<>"",INDEX(tb_MainDatabase[Grand],MATCH(F15,tb_MainDatabase[Link],0)),"")} -> EDP | I15: {=IF(F15<>"",INDEX(tb_MainDatabase[Size],MATCH(F15,tb_MainDatabase[Link],0)),"")} -> 4 ml. | J15: 1 | K15: {=IF(F15<>"",INDEX(tb_MainDatabase[ราคา],MATCH(F15,tb_MainDatabase[Link],0)),"")*J15} -> 179 | L15: 179 | M15: =K15-(L15*J15) -> 0 | N15: =SUMIF($D$3:D3231,R15,$M$3:M3231) -> 0 | R15: =IF(COUNTIF(D$3:D15, D15)>1, 0, D15) -> 0
A16: Nov-25 | B16: 45982 | C16: Pure, Jom | D16: 1763696917196248249 | E16: 202500000000031 | F16: Cloth BAG CYOCSize M | G16: {=IF(F16<>"",INDEX(tb_MainDatabase[Barcode],MATCH(F16,tb_MainDatabase[Link],0)),"")} -> 8857128012132 | H16: {=IF(F16<>"",INDEX(tb_MainDatabase[Grand],MATCH(F16,tb_MainDatabase[Link],0)),"")} -> Cloth | I16: {=IF(F16<>"",INDEX(tb_MainDatabase[Size],MATCH(F16,tb_MainDatabase[Link],0)),"")} -> Size M | J16: 1 | K16: {=IF(F16<>"",INDEX(tb_MainDatabase[ราคา],MATCH(F16,tb_MainDatabase[Link],0)),"")*J16} -> 0 | M16: =K16-(L16*J16) -> 0 | N16: =SUMIF($D$3:D3232,R16,$M$3:M3232) -> 0 | R16: =IF(COUNTIF(D$3:D16, D16)>1, 0, D16) -> 0
A17: Nov-25 | B17: 45982 | C17: Pure, Jom | D17: 1763696917196248249 | E17: 202500000000031 | F17: Tumbler CYOC (Dark Blue)Dark Blue | G17: {=IF(F17<>"",INDEX(tb_MainDatabase[Barcode],MATCH(F17,tb_MainDatabase[Link],0)),"")} -> 8857128012131 | H17: {=IF(F17<>"",INDEX(tb_MainDatabase[Grand],MATCH(F17,tb_MainDatabase[Link],0)),"")} -> Tumbler | I17: {=IF(F17<>"",INDEX(tb_MainDatabase[Size],MATCH(F17,tb_MainDatabase[Link],0)),"")} -> Dark Blue | J17: 1 | K17: {=IF(F17<>"",INDEX(tb_MainDatabase[ราคา],MATCH(F17,tb_MainDatabase[Link],0)),"")*J17} -> 0 | M17: =K17-(L17*J17) -> 0 | N17: =SUMIF($D$3:D3233,R17,$M$3:M3233) -> 0 | R17: =IF(COUNTIF(D$3:D17, D17)>1, 0, D17) -> 0
A18: Nov-25 | B18: 45982 | C18: Pure, Jom | D18: 1763698140402109979 | E18: 202500000000032 | F18: Voyage50 ml. | G18: {=IF(F18<>"",INDEX(tb_MainDatabase[Barcode],MATCH(F18,tb_MainDatabase[Link],0)),"")} -> 8857128012019 | H18: {=IF(F18<>"",INDEX(tb_MainDatabase[Grand],MATCH(F18,tb_MainDatabase[Link],0)),"")} -> EDP | I18: {=IF(F18<>"",INDEX(tb_MainDatabase[Size],MATCH(F18,tb_MainDatabase[Link],0)),"")} -> 50 ml. | J18: 2 | K18: {=IF(F18<>"",INDEX(tb_MainDatabase[ราคา],MATCH(F18,tb_MainDatabase[Link],0)),"")*J18} -> 3780 | L18: 500 | M18: =K18-(L18*J18) -> 2780 | N18: =SUMIF($D$3:D3234,R18,$M$3:M3234) -> 5560 | O18: K Shop Credit Card | P18: 45982 | Q18: 0.46527778 | R18: =IF(COUNTIF(D$3:D18, D18)>1, 0, D18) -> 1763698140402109979
A19: Nov-25 | B19: 45982 | C19: Pure, Jom | D19: 1763698140402109979 | E19: 202500000000032 | F19: La Belle50 ml. | G19: {=IF(F19<>"",INDEX(tb_MainDatabase[Barcode],MATCH(F19,tb_MainDatabase[Link],0)),"")} -> 8857128011058 | H19: {=IF(F19<>"",INDEX(tb_MainDatabase[Grand],MATCH(F19,tb_MainDatabase[Link],0)),"")} -> EDP | I19: {=IF(F19<>"",INDEX(tb_MainDatabase[Size],MATCH(F19,tb_MainDatabase[Link],0)),"")} -> 50 ml. | J19: 2 | K19: {=IF(F19<>"",INDEX(tb_MainDatabase[ราคา],MATCH(F19,tb_MainDatabase[Link],0)),"")*J19} -> 3780 | L19: 500 | M19: =K19-(L19*J19) -> 2780 | N19: =SUMIF($D$3:D3235,R19,$M$3:M3235) -> 0 | R19: =IF(COUNTIF(D$3:D19, D19)>1, 0, D19) -> 0
A20: Nov-25 | B20: 45982 | C20: Pure, Jom | D20: 1763698140402109979 | E20: 202500000000032 | F20: Senorita4 ml. | G20: {=IF(F20<>"",INDEX(tb_MainDatabase[Barcode],MATCH(F20,tb_MainDatabase[Link],0)),"")} -> 8857128012040 | H20: {=IF(F20<>"",INDEX(tb_MainDatabase[Grand],MATCH(F20,tb_MainDatabase[Link],0)),"")} -> EDP | I20: {=IF(F20<>"",INDEX(tb_MainDatabase[Size],MATCH(F20,tb_MainDatabase[Link],0)),"")} -> 4 ml. | J20: 1 | K20: {=IF(F20<>"",INDEX(tb_MainDatabase[ราคา],MATCH(F20,tb_MainDatabase[Link],0)),"")*J20} -> 179 | L20: 179 | M20: =K20-(L20*J20) -> 0 | N20: =SUMIF($D$3:D3236,R20,$M$3:M3236) -> 0 | R20: =IF(COUNTIF(D$3:D20, D20)>1, 0, D20) -> 0
A21: Nov-25 | B21: 45982 | C21: Pure, Jom | D21: 1763698140402109979 | E21: 202500000000032 | F21: Buoyant4 ml. | G21: {=IF(F21<>"",INDEX(tb_MainDatabase[Barcode],MATCH(F21,tb_MainDatabase[Link],0)),"")} -> 8857128012078 | H21: {=IF(F21<>"",INDEX(tb_MainDatabase[Grand],MATCH(F21,tb_MainDatabase[Link],0)),"")} -> EDP | I21: {=IF(F21<>"",INDEX(tb_MainDatabase[Size],MATCH(F21,tb_MainDatabase[Link],0)),"")} -> 4 ml. | J21: 1 | K21: {=IF(F21<>"",INDEX(tb_MainDatabase[ราคา],MATCH(F21,tb_MainDatabase[Link],0)),"")*J21} -> 179 | L21: 179 | M21: =K21-(L21*J21) -> 0 | N21: =SUMIF($D$3:D3237,R21,$M$3:M3237) -> 0 | R21: =IF(COUNTIF(D$3:D21, D21)>1, 0, D21) -> 0
A22: Nov-25 | B22: 45982 | C22: Pure, Jom | D22: 1763698140402109979 | E22: 202500000000032 | F22: Cloth BAG CYOCSize M | G22: {=IF(F22<>"",INDEX(tb_MainDatabase[Barcode],MATCH(F22,tb_MainDatabase[Link],0)),"")} -> 8857128012132 | H22: {=IF(F22<>"",INDEX(tb_MainDatabase[Grand],MATCH(F22,tb_MainDatabase[Link],0)),"")} -> Cloth | I22: {=IF(F22<>"",INDEX(tb_MainDatabase[Size],MATCH(F22,tb_MainDatabase[Link],0)),"")} -> Size M | J22: 1 | K22: {=IF(F22<>"",INDEX(tb_MainDatabase[ราคา],MATCH(F22,tb_MainDatabase[Link],0)),"")*J22} -> 0 | M22: =K22-(L22*J22) -> 0 | N22: =SUMIF($D$3:D3238,R22,$M$3:M3238) -> 0 | R22: =IF(COUNTIF(D$3:D22, D22)>1, 0, D22) -> 0
A23: Nov-25 | B23: 45982 | C23: Pure, Jom | D23: 1763698140402109979 | E23: 202500000000032 | F23: Tumbler CYOC (Dark Blue)Dark Blue | G23: {=IF(F23<>"",INDEX(tb_MainDatabase[Barcode],MATCH(F23,tb_MainDatabase[Link],0)),"")} -> 8857128012131 | H23: {=IF(F23<>"",INDEX(tb_MainDatabase[Grand],MATCH(F23,tb_MainDatabase[Link],0)),"")} -> Tumbler | I23: {=IF(F23<>"",INDEX(tb_MainDatabase[Size],MATCH(F23,tb_MainDatabase[Link],0)),"")} -> Dark Blue | J23: 1 | K23: {=IF(F23<>"",INDEX(tb_MainDatabase[ราคา],MATCH(F23,tb_MainDatabase[Link],0)),"")*J23} -> 0 | M23: =K23-(L23*J23) -> 0 | N23: =SUMIF($D$3:D3239,R23,$M$3:M3239) -> 0 | R23: =IF(COUNTIF(D$3:D23, D23)>1, 0, D23) -> 0
A24: Nov-25 | B24: 45982 | C24: Pure, Jom | D24: 1763723255137677400 | E24: 202500000000033 | F24: La Belle10 ml. | G24: {=IF(F24<>"",INDEX(tb_MainDatabase[Barcode],MATCH(F24,tb_MainDatabase[Link],0)),"")} -> 8857128012034 | H24: {=IF(F24<>"",INDEX(tb_MainDatabase[Grand],MATCH(F24,tb_MainDatabase[Link],0)),"")} -> EDP | I24: {=IF(F24<>"",INDEX(tb_MainDatabase[Size],MATCH(F24,tb_MainDatabase[Link],0)),"")} -> 10 ml. | J24: 1 | K24: {=IF(F24<>"",INDEX(tb_MainDatabase[ราคา],MATCH(F24,tb_MainDatabase[Link],0)),"")*J24} -> 450 | L24: 100 | M24: =K24-(L24*J24) -> 350 | N24: =SUMIF($D$3:D3240,R24,$M$3:M3240) -> 350 | O24: Cash | P24: 45982 | R24: =IF(COUNTIF(D$3:D24, D24)>1, 0, D24) -> 1763723255137677400
A25: Nov-25 | B25: 45982 | C25: Pure, Jom | D25: 1763723391005795009 | E25: 202500000000034 | F25: La Belle30 ml. | G25: {=IF(F25<>"",INDEX(tb_MainDatabase[Barcode],MATCH(F25,tb_MainDatabase[Link],0)),"")} -> 8857128011904 | H25: {=IF(F25<>"",INDEX(tb_MainDatabase[Grand],MATCH(F25,tb_MainDatabase[Link],0)),"")} -> EDP | I25: {=IF(F25<>"",INDEX(tb_MainDatabase[Size],MATCH(F25,tb_MainDatabase[Link],0)),"")} -> 30 ml. | J25: 1 | K25: {=IF(F25<>"",INDEX(tb_MainDatabase[ราคา],MATCH(F25,tb_MainDatabase[Link],0)),"")*J25} -> 1290 | L25: 300 | M25: =K25-(L25*J25) -> 990 | N25: =SUMIF($D$3:D3241,R25,$M$3:M3241) -> 990 | O25: K Shop | P25: 45982 | Q25: 0.75694444 | R25: =IF(COUNTIF(D$3:D25, D25)>1, 0, D25) -> 1763723391005795009
A26: Nov-25 | B26: 45982 | C26: Pure, Jom | D26: 1763723391005795009 | E26: 202500000000034 | F26: Senorita4 ml. | G26: {=IF(F26<>"",INDEX(tb_MainDatabase[Barcode],MATCH(F26,tb_MainDatabase[Link],0)),"")} -> 8857128012040 | H26: {=IF(F26<>"",INDEX(tb_MainDatabase[Grand],MATCH(F26,tb_MainDatabase[Link],0)),"")} -> EDP | I26: {=IF(F26<>"",INDEX(tb_MainDatabase[Size],MATCH(F26,tb_MainDatabase[Link],0)),"")} -> 4 ml. | J26: 1 | K26: {=IF(F26<>"",INDEX(tb_MainDatabase[ราคา],MATCH(F26,tb_MainDatabase[Link],0)),"")*J26} -> 179 | L26: 179 | M26: =K26-(L26*J26) -> 0 | N26: =SUMIF($D$3:D3242,R26,$M$3:M3242) -> 0 | R26: =IF(COUNTIF(D$3:D26, D26)>1, 0, D26) -> 0
A27: Nov-25 | B27: 45982 | C27: Pure, Jom | D27: 1763725916681766418 | E27: 202500000000035 | F27: Persist50 ml. | G27: {=IF(F27<>"",INDEX(tb_MainDatabase[Barcode],MATCH(F27,tb_MainDatabase[Link],0)),"")} -> 8857128011041 | H27: {=IF(F27<>"",INDEX(tb_MainDatabase[Grand],MATCH(F27,tb_MainDatabase[Link],0)),"")} -> EDP | I27: {=IF(F27<>"",INDEX(tb_MainDatabase[Size],MATCH(F27,tb_MainDatabase[Link],0)),"")} -> 50 ml. | J27: 1 | K27: {=IF(F27<>"",INDEX(tb_MainDatabase[ราคา],MATCH(F27,tb_MainDatabase[Link],0)),"")*J27} -> 1890 | L27: 500 | M27: =K27-(L27*J27) -> 1390 | N27: =SUMIF($D$3:D3243,R27,$M$3:M3243) -> 2780 | O27: K Shop Credit Card | P27: 45982 | Q27: 0.79930556 | R27: =IF(COUNTIF(D$3:D27, D27)>1, 0, D27) -> 1763725916681766418
A28: Nov-25 | B28: 45982 | C28: Pure, Jom | D28: 1763725916681766418 | E28: 202500000000035 | F28: Zeus50 ml. | G28: {=IF(F28<>"",INDEX(tb_MainDatabase[Barcode],MATCH(F28,tb_MainDatabase[Link],0)),"")} -> 8857128011027 | H28: {=IF(F28<>"",INDEX(tb_MainDatabase[Grand],MATCH(F28,tb_MainDatabase[Link],0)),"")} -> EDP | I28: {=IF(F28<>"",INDEX(tb_MainDatabase[Size],MATCH(F28,tb_MainDatabase[Link],0)),"")} -> 50 ml. | J28: 1 | K28: {=IF(F28<>"",INDEX(tb_MainDatabase[ราคา],MATCH(F28,tb_MainDatabase[Link],0)),"")*J28} -> 1890 | L28: 500 | M28: =K28-(L28*J28) -> 1390 | N28: =SUMIF($D$3:D3244,R28,$M$3:M3244) -> 0 | R28: =IF(COUNTIF(D$3:D28, D28)>1, 0, D28) -> 0
A29: Nov-25 | B29: 45982 | C29: Pure, Jom | D29: 1763725916681766418 | E29: 202500000000035 | F29: La Belle4 ml. | G29: {=IF(F29<>"",INDEX(tb_MainDatabase[Barcode],MATCH(F29,tb_MainDatabase[Link],0)),"")} -> 8857128012016 | H29: {=IF(F29<>"",INDEX(tb_MainDatabase[Grand],MATCH(F29,tb_MainDatabase[Link],0)),"")} -> EDP | I29: {=IF(F29<>"",INDEX(tb_MainDatabase[Size],MATCH(F29,tb_MainDatabase[Link],0)),"")} -> 4 ml. | J29: 1 | K29: {=IF(F29<>"",INDEX(tb_MainDatabase[ราคา],MATCH(F29,tb_MainDatabase[Link],0)),"")*J29} -> 179 | L29: 179 | M29: =K29-(L29*J29) -> 0 | N29: =SUMIF($D$3:D3245,R29,$M$3:M3245) -> 0 | R29: =IF(COUNTIF(D$3:D29, D29)>1, 0, D29) -> 0
A30: Nov-25 | B30: 45982 | C30: Pure, Jom | D30: 1763725916681766418 | E30: 202500000000035 | F30: Never Blue4 ml. | G30: {=IF(F30<>"",INDEX(tb_MainDatabase[Barcode],MATCH(F30,tb_MainDatabase[Link],0)),"")} -> 8857128012036 | H30: {=IF(F30<>"",INDEX(tb_MainDatabase[Grand],MATCH(F30,tb_MainDatabase[Link],0)),"")} -> EDP | I30: {=IF(F30<>"",INDEX(tb_MainDatabase[Size],MATCH(F30,tb_MainDatabase[Link],0)),"")} -> 4 ml. | J30: 1 | K30: {=IF(F30<>"",INDEX(tb_MainDatabase[ราคา],MATCH(F30,tb_MainDatabase[Link],0)),"")*J30} -> 179 | L30: 179 | M30: =K30-(L30*J30) -> 0 | N30: =SUMIF($D$3:D3246,R30,$M$3:M3246) -> 0 | R30: =IF(COUNTIF(D$3:D30, D30)>1, 0, D30) -> 0
A31: Nov-25 | B31: 45982 | C31: Pure, Jom | D31: 1763725916681766418 | E31: 202500000000035 | F31: Tumbler CYOC (White)White | G31: {=IF(F31<>"",INDEX(tb_MainDatabase[Barcode],MATCH(F31,tb_MainDatabase[Link],0)),"")} -> 8857128012130 | H31: {=IF(F31<>"",INDEX(tb_MainDatabase[Grand],MATCH(F31,tb_MainDatabase[Link],0)),"")} -> Tumbler | I31: {=IF(F31<>"",INDEX(tb_MainDatabase[Size],MATCH(F31,tb_MainDatabase[Link],0)),"")} -> White | J31: 1 | K31: {=IF(F31<>"",INDEX(tb_MainDatabase[ราคา],MATCH(F31,tb_MainDatabase[Link],0)),"")*J31} -> 0 | M31: =K31-(L31*J31) -> 0 | N31: =SUMIF($D$3:D3247,R31,$M$3:M3247) -> 0 | R31: =IF(COUNTIF(D$3:D31, D31)>1, 0, D31) -> 0
A32: Nov-25 | B32: 45983 | C32: Note, Jom | D32: 1763729894310594281 | E32: 202500000000036 | F32: La Belle30 ml. | G32: {=IF(F32<>"",INDEX(tb_MainDatabase[Barcode],MATCH(F32,tb_MainDatabase[Link],0)),"")} -> 8857128011904 | H32: {=IF(F32<>"",INDEX(tb_MainDatabase[Grand],MATCH(F32,tb_MainDatabase[Link],0)),"")} -> EDP | I32: {=IF(F32<>"",INDEX(tb_MainDatabase[Size],MATCH(F32,tb_MainDatabase[Link],0)),"")} -> 30 ml. | J32: 1 | K32: {=IF(F32<>"",INDEX(tb_MainDatabase[ราคา],MATCH(F32,tb_MainDatabase[Link],0)),"")*J32} -> 1290 | L32: 300 | M32: =K32-(L32*J32) -> 990 | N32: =SUMIF($D$3:D3248,R32,$M$3:M3248) -> 990 | O32: K Shop Credit Card | P32: 45983 | Q32: 0.45416667 | R32: =IF(COUNTIF(D$3:D32, D32)>1, 0, D32) -> 1763729894310594281
A33: Nov-25 | B33: 45983 | C33: Note, Jom | D33: 1763783729225970189 | E33: 202500000000037 | F33: Zeus50 ml. | G33: {=IF(F33<>"",INDEX(tb_MainDatabase[Barcode],MATCH(F33,tb_MainDatabase[Link],0)),"")} -> 8857128011027 | H33: {=IF(F33<>"",INDEX(tb_MainDatabase[Grand],MATCH(F33,tb_MainDatabase[Link],0)),"")} -> EDP | I33: {=IF(F33<>"",INDEX(tb_MainDatabase[Size],MATCH(F33,tb_MainDatabase[Link],0)),"")} -> 50 ml. | J33: 1 | K33: {=IF(F33<>"",INDEX(tb_MainDatabase[ราคา],MATCH(F33,tb_MainDatabase[Link],0)),"")*J33} -> 1890 | L33: 500 | M33: =K33-(L33*J33) -> 1390 | N33: =SUMIF($D$3:D3249,R33,$M$3:M3249) -> 2780 | O33: Cash | P33: 45983 | R33: =IF(COUNTIF(D$3:D33, D33)>1, 0, D33) -> 1763783729225970189
A34: Nov-25 | B34: 45983 | C34: Note, Jom | D34: 1763783729225970189 | E34: 202500000000037 | F34: Aqua50 ml. | G34: {=IF(F34<>"",INDEX(tb_MainDatabase[Barcode],MATCH(F34,tb_MainDatabase[Link],0)),"")} -> 8857128012018 | H34: {=IF(F34<>"",INDEX(tb_MainDatabase[Grand],MATCH(F34,tb_MainDatabase[Link],0)),"")} -> EDP | I34: {=IF(F34<>"",INDEX(tb_MainDatabase[Size],MATCH(F34,tb_MainDatabase[Link],0)),"")} -> 50 ml. | J34: 1 | K34: {=IF(F34<>"",INDEX(tb_MainDatabase[ราคา],MATCH(F34,tb_MainDatabase[Link],0)),"")*J34} -> 1890 | L34: 500 | M34: =K34-(L34*J34) -> 1390 | N34: =SUMIF($D$3:D3250,R34,$M$3:M3250) -> 0 | R34: =IF(COUNTIF(D$3:D34, D34)>1, 0, D34) -> 0
A35: Nov-25 | B35: 45983 | C35: Note, Jom | D35: 1763783729225970189 | E35: 202500000000037 | F35: Sicilia4 ml. | G35: {=IF(F35<>"",INDEX(tb_MainDatabase[Barcode],MATCH(F35,tb_MainDatabase[Link],0)),"")} -> 8857128012056 | H35: {=IF(F35<>"",INDEX(tb_MainDatabase[Grand],MATCH(F35,tb_MainDatabase[Link],0)),"")} -> EDP | I35: {=IF(F35<>"",INDEX(tb_MainDatabase[Size],MATCH(F35,tb_MainDatabase[Link],0)),"")} -> 4 ml. | J35: 1 | K35: {=IF(F35<>"",INDEX(tb_MainDatabase[ราคา],MATCH(F35,tb_MainDatabase[Link],0)),"")*J35} -> 179 | L35: 179 | M35: =K35-(L35*J35) -> 0 | N35: =SUMIF($D$3:D3251,R35,$M$3:M3251) -> 0 | R35: =IF(COUNTIF(D$3:D35, D35)>1, 0, D35) -> 0
A36: Nov-25 | B36: 45983 | C36: Note, Jom | D36: 1763783729225970189 | E36: 202500000000037 | F36: Tumbler CYOC (White)White | G36: {=IF(F36<>"",INDEX(tb_MainDatabase[Barcode],MATCH(F36,tb_MainDatabase[Link],0)),"")} -> 8857128012130 | H36: {=IF(F36<>"",INDEX(tb_MainDatabase[Grand],MATCH(F36,tb_MainDatabase[Link],0)),"")} -> Tumbler | I36: {=IF(F36<>"",INDEX(tb_MainDatabase[Size],MATCH(F36,tb_MainDatabase[Link],0)),"")} -> White | J36: 1 | K36: {=IF(F36<>"",INDEX(tb_MainDatabase[ราคา],MATCH(F36,tb_MainDatabase[Link],0)),"")*J36} -> 0 | M36: =K36-(L36*J36) -> 0 | N36: =SUMIF($D$3:D3252,R36,$M$3:M3252) -> 0 | R36: =IF(COUNTIF(D$3:D36, D36)>1, 0, D36) -> 0
A37: Nov-25 | B37: 45983 | C37: Note, Jom | D37: 1763790727877590536 | E37: 202500000000038 | F37: Never Blue50 ml. | G37: {=IF(F37<>"",INDEX(tb_MainDatabase[Barcode],MATCH(F37,tb_MainDatabase[Link],0)),"")} -> 8857128011287 | H37: {=IF(F37<>"",INDEX(tb_MainDatabase[Grand],MATCH(F37,tb_MainDatabase[Link],0)),"")} -> EDP | I37: {=IF(F37<>"",INDEX(tb_MainDatabase[Size],MATCH(F37,tb_MainDatabase[Link],0)),"")} -> 50 ml. | J37: 1 | K37: {=IF(F37<>"",INDEX(tb_MainDatabase[ราคา],MATCH(F37,tb_MainDatabase[Link],0)),"")*J37} -> 1890 | L37: 1890 | M37: =K37-(L37*J37) -> 0 | N37: =SUMIF($D$3:D3253,R37,$M$3:M3253) -> 0 | R37: =IF(COUNTIF(D$3:D37, D37)>1, 0, D37) -> 1763790727877590536
A38: Nov-25 | B38: 45983 | C38: Note, Jom | D38: 1763790727877590536 | E38: 202500000000038 | F38: Persist50 ml. | G38: {=IF(F38<>"",INDEX(tb_MainDatabase[Barcode],MATCH(F38,tb_MainDatabase[Link],0)),"")} -> 8857128011041 | H38: {=IF(F38<>"",INDEX(tb_MainDatabase[Grand],MATCH(F38,tb_MainDatabase[Link],0)),"")} -> EDP | I38: {=IF(F38<>"",INDEX(tb_MainDatabase[Size],MATCH(F38,tb_MainDatabase[Link],0)),"")} -> 50 ml. | J38: 1 | K38: {=IF(F38<>"",INDEX(tb_MainDatabase[ราคา],MATCH(F38,tb_MainDatabase[Link],0)),"")*J38} -> 1890 | L38: 1890 | M38: =K38-(L38*J38) -> 0 | N38: =SUMIF($D$3:D3254,R38,$M$3:M3254) -> 0 | R38: =IF(COUNTIF(D$3:D38, D38)>1, 0, D38) -> 0
A39: Nov-25 | B39: 45983 | C39: Note, Jom | D39: 1763799660948781545 | E39: 202500000000039 | F39: Persist50 ml. | G39: {=IF(F39<>"",INDEX(tb_MainDatabase[Barcode],MATCH(F39,tb_MainDatabase[Link],0)),"")} -> 8857128011041 | H39: {=IF(F39<>"",INDEX(tb_MainDatabase[Grand],MATCH(F39,tb_MainDatabase[Link],0)),"")} -> EDP | I39: {=IF(F39<>"",INDEX(tb_MainDatabase[Size],MATCH(F39,tb_MainDatabase[Link],0)),"")} -> 50 ml. | J39: 1 | K39: {=IF(F39<>"",INDEX(tb_MainDatabase[ราคา],MATCH(F39,tb_MainDatabase[Link],0)),"")*J39} -> 1890 | L39: 1890 | M39: =K39-(L39*J39) -> 0 | N39: =SUMIF($D$3:D3255,R39,$M$3:M3255) -> 0 | R39: =IF(COUNTIF(D$3:D39, D39)>1, 0, D39) -> 1763799660948781545
A40: Nov-25 | B40: 45983 | C40: Note, Jom | D40: 1763802160509215883 | E40: 202500000000041 | F40: Eden50 ml. | G40: {=IF(F40<>"",INDEX(tb_MainDatabase[Barcode],MATCH(F40,tb_MainDatabase[Link],0)),"")} -> 8857128011317 | H40: {=IF(F40<>"",INDEX(tb_MainDatabase[Grand],MATCH(F40,tb_MainDatabase[Link],0)),"")} -> EDP | I40: {=IF(F40<>"",INDEX(tb_MainDatabase[Size],MATCH(F40,tb_MainDatabase[Link],0)),"")} -> 50 ml. | J40: 1 | K40: {=IF(F40<>"",INDEX(tb_MainDatabase[ราคา],MATCH(F40,tb_MainDatabase[Link],0)),"")*J40} -> 1890 | L40: 1890 | M40: =K40-(L40*J40) -> 0 | N40: =SUMIF($D$3:D3256,R40,$M$3:M3256) -> 0 | R40: =IF(COUNTIF(D$3:D40, D40)>1, 0, D40) -> 1763802160509215883
...

Sheet Sell EVENT SCS
J1: =SUM(J3:J184) -> 171 | K1: =SUM(K3:K184) -> 152390 | L1: =SUM(L3:L184) -> 31450 | M1: =SUM(M3:M184) -> 119940 | N1: =SUM(N3:N184) -> 119940
A2: Month | B2: วันที่ | C2: BA | D2: เลขที่คำสั่งซื้อ | E2: เลขที่ใบเสร็จ | F2: รายการ | G2: Barcode | H2: Grand | I2: Size | J2: จำนวน | K2: ราคา | L2: ส่วนลด | M2: รวม | N2: ยอดชำระ | O2: ช่องทางชำระ | P2: Date | Q2: Time | R2: UID | S2: หมายเหตุ | T2: Nation
A3: Jul-26 | B3: 46212 | C3: Jom, Beam | D3: EVSCS20260709001 | F3: Secret of Peach30 ml. | G3: {=IF(F3<>"",INDEX(tb_MainDatabase[Barcode],MATCH(F3,tb_MainDatabase[Link],0)),"")} -> 8857128011850 | H3: {=IF(F3<>"",INDEX(tb_MainDatabase[Grand],MATCH(F3,tb_MainDatabase[Link],0)),"")} -> EDP | I3: {=IF(F3<>"",INDEX(tb_MainDatabase[Size],MATCH(F3,tb_MainDatabase[Link],0)),"")} -> 30 ml. | J3: 1 | K3: {=IF(F3<>"",INDEX(tb_MainDatabase[ราคา],MATCH(F3,tb_MainDatabase[Link],0)),"")*J3} -> 1290 | L3: 300 | M3: =K3-(L3*J3) -> 990 | N3: =SUMIF($D$3:D184,R3,$M$3:M184) -> 990 | O3: K Shop | P3: 46212 | Q3: 0.53055556 | R3: =IF(COUNTIF(D$3:D3, D3)>1, 0, D3) -> EVSCS20260709001 | T3: Thai
A4: Jul-26 | B4: 46212 | C4: Jom, Beam | D4: EVSCS20260709002 | F4: Never Blue30 ml. | G4: {=IF(F4<>"",INDEX(tb_MainDatabase[Barcode],MATCH(F4,tb_MainDatabase[Link],0)),"")} -> 8857128011836 | H4: {=IF(F4<>"",INDEX(tb_MainDatabase[Grand],MATCH(F4,tb_MainDatabase[Link],0)),"")} -> EDP | I4: {=IF(F4<>"",INDEX(tb_MainDatabase[Size],MATCH(F4,tb_MainDatabase[Link],0)),"")} -> 30 ml. | J4: 1 | K4: {=IF(F4<>"",INDEX(tb_MainDatabase[ราคา],MATCH(F4,tb_MainDatabase[Link],0)),"")*J4} -> 1290 | L4: 300 | M4: =K4-(L4*J4) -> 990 | N4: =SUMIF($D$3:D185,R4,$M$3:M185) -> 990 | O4: K Shop | P4: 46214 | Q4: 0.65694444 | R4: =IF(COUNTIF(D$3:D4, D4)>1, 0, D4) -> EVSCS20260709002 | T4: Foreign
A5: Jul-26 | B5: 46212 | C5: Jom, Beam | D5: EVSCS20260709003 | F5: Aqua30 ml. | G5: {=IF(F5<>"",INDEX(tb_MainDatabase[Barcode],MATCH(F5,tb_MainDatabase[Link],0)),"")} -> 8857128012022 | H5: {=IF(F5<>"",INDEX(tb_MainDatabase[Grand],MATCH(F5,tb_MainDatabase[Link],0)),"")} -> EDP | I5: {=IF(F5<>"",INDEX(tb_MainDatabase[Size],MATCH(F5,tb_MainDatabase[Link],0)),"")} -> 30 ml. | J5: 1 | K5: {=IF(F5<>"",INDEX(tb_MainDatabase[ราคา],MATCH(F5,tb_MainDatabase[Link],0)),"")*J5} -> 1290 | L5: 300 | M5: =K5-(L5*J5) -> 990 | N5: =SUMIF($D$3:D186,R5,$M$3:M186) -> 990 | O5: K Shop | P5: 46212 | Q5: 0.63263889 | R5: =IF(COUNTIF(D$3:D5, D5)>1, 0, D5) -> EVSCS20260709003 | T5: Foreign
A6: Jul-26 | B6: 46212 | C6: Jom, Beam | D6: EVSCS20260709004 | F6: Secret of Peach30 ml. | G6: {=IF(F6<>"",INDEX(tb_MainDatabase[Barcode],MATCH(F6,tb_MainDatabase[Link],0)),"")} -> 8857128011850 | H6: {=IF(F6<>"",INDEX(tb_MainDatabase[Grand],MATCH(F6,tb_MainDatabase[Link],0)),"")} -> EDP | I6: {=IF(F6<>"",INDEX(tb_MainDatabase[Size],MATCH(F6,tb_MainDatabase[Link],0)),"")} -> 30 ml. | J6: 1 | K6: {=IF(F6<>"",INDEX(tb_MainDatabase[ราคา],MATCH(F6,tb_MainDatabase[Link],0)),"")*J6} -> 1290 | L6: 300 | M6: =K6-(L6*J6) -> 990 | N6: =SUMIF($D$3:D187,R6,$M$3:M187) -> 990 | O6: K Shop | P6: 46212 | Q6: 0.67013889 | R6: =IF(COUNTIF(D$3:D6, D6)>1, 0, D6) -> EVSCS20260709004 | T6: Thai
A7: Jul-26 | B7: 46212 | C7: Jom, Beam | D7: EVSCS20260709005 | F7: Dream Island10 ml. | G7: {=IF(F7<>"",INDEX(tb_MainDatabase[Barcode],MATCH(F7,tb_MainDatabase[Link],0)),"")} -> 8857128012030 | H7: {=IF(F7<>"",INDEX(tb_MainDatabase[Grand],MATCH(F7,tb_MainDatabase[Link],0)),"")} -> EDP | I7: {=IF(F7<>"",INDEX(tb_MainDatabase[Size],MATCH(F7,tb_MainDatabase[Link],0)),"")} -> 10 ml. | J7: 1 | K7: {=IF(F7<>"",INDEX(tb_MainDatabase[ราคา],MATCH(F7,tb_MainDatabase[Link],0)),"")*J7} -> 450 | L7: 100 | M7: =K7-(L7*J7) -> 350 | N7: =SUMIF($D$3:D188,R7,$M$3:M188) -> 350 | O7: K Shop | P7: 46212 | Q7: 0.73125 | R7: =IF(COUNTIF(D$3:D7, D7)>1, 0, D7) -> EVSCS20260709005 | T7: Thai
A8: Jul-26 | B8: 46212 | C8: Jom, Beam | D8: EVSCS20260709006 | F8: Secret of Peach50 ml. | G8: {=IF(F8<>"",INDEX(tb_MainDatabase[Barcode],MATCH(F8,tb_MainDatabase[Link],0)),"")} -> 8857128011119 | H8: {=IF(F8<>"",INDEX(tb_MainDatabase[Grand],MATCH(F8,tb_MainDatabase[Link],0)),"")} -> EDP | I8: {=IF(F8<>"",INDEX(tb_MainDatabase[Size],MATCH(F8,tb_MainDatabase[Link],0)),"")} -> 50 ml. | J8: 1 | K8: {=IF(F8<>"",INDEX(tb_MainDatabase[ราคา],MATCH(F8,tb_MainDatabase[Link],0)),"")*J8} -> 1890 | L8: 400 | M8: =K8-(L8*J8) -> 1490 | N8: =SUMIF($D$3:D189,R8,$M$3:M189) -> 1490 | O8: K Shop | P8: 46212 | Q8: 0.77847222 | R8: =IF(COUNTIF(D$3:D8, D8)>1, 0, D8) -> EVSCS20260709006 | T8: Thai
A9: Jul-26 | B9: 46212 | C9: Jom, Beam | D9: EVSCS20260709007 | F9: Zeus10 ml. | G9: {=IF(F9<>"",INDEX(tb_MainDatabase[Barcode],MATCH(F9,tb_MainDatabase[Link],0)),"")} -> 8857128012041 | H9: {=IF(F9<>"",INDEX(tb_MainDatabase[Grand],MATCH(F9,tb_MainDatabase[Link],0)),"")} -> EDP | I9: {=IF(F9<>"",INDEX(tb_MainDatabase[Size],MATCH(F9,tb_MainDatabase[Link],0)),"")} -> 10 ml. | J9: 1 | K9: {=IF(F9<>"",INDEX(tb_MainDatabase[ราคา],MATCH(F9,tb_MainDatabase[Link],0)),"")*J9} -> 450 | L9: 100 | M9: =K9-(L9*J9) -> 350 | N9: =SUMIF($D$3:D190,R9,$M$3:M190) -> 350 | O9: K Shop | P9: 46212 | Q9: 0.74722222 | R9: =IF(COUNTIF(D$3:D9, D9)>1, 0, D9) -> EVSCS20260709007 | T9: Thai
A10: Jul-26 | B10: 46212 | C10: Jom, Beam | D10: EVSCS20260709008 | F10: Secret of Peach50 ml. | G10: {=IF(F10<>"",INDEX(tb_MainDatabase[Barcode],MATCH(F10,tb_MainDatabase[Link],0)),"")} -> 8857128011119 | H10: {=IF(F10<>"",INDEX(tb_MainDatabase[Grand],MATCH(F10,tb_MainDatabase[Link],0)),"")} -> EDP | I10: {=IF(F10<>"",INDEX(tb_MainDatabase[Size],MATCH(F10,tb_MainDatabase[Link],0)),"")} -> 50 ml. | J10: 1 | K10: {=IF(F10<>"",INDEX(tb_MainDatabase[ราคา],MATCH(F10,tb_MainDatabase[Link],0)),"")*J10} -> 1890 | L10: 400 | M10: =K10-(L10*J10) -> 1490 | N10: =SUMIF($D$3:D191,R10,$M$3:M191) -> 1840 | O10: K Shop | P10: 46212 | Q10: 0.81597222 | R10: =IF(COUNTIF(D$3:D10, D10)>1, 0, D10) -> EVSCS20260709008 | T10: Thai
A11: Jul-26 | B11: 46212 | C11: Jom, Beam | D11: EVSCS20260709008 | F11: Senorita10 ml. | G11: {=IF(F11<>"",INDEX(tb_MainDatabase[Barcode],MATCH(F11,tb_MainDatabase[Link],0)),"")} -> 8857128012039 | H11: {=IF(F11<>"",INDEX(tb_MainDatabase[Grand],MATCH(F11,tb_MainDatabase[Link],0)),"")} -> EDP | I11: {=IF(F11<>"",INDEX(tb_MainDatabase[Size],MATCH(F11,tb_MainDatabase[Link],0)),"")} -> 10 ml. | J11: 1 | K11: {=IF(F11<>"",INDEX(tb_MainDatabase[ราคา],MATCH(F11,tb_MainDatabase[Link],0)),"")*J11} -> 450 | L11: 100 | M11: =K11-(L11*J11) -> 350 | N11: =SUMIF($D$3:D192,R11,$M$3:M192) -> 0 | R11: =IF(COUNTIF(D$3:D11, D11)>1, 0, D11) -> 0
A12: Jul-26 | B12: 46212 | C12: Jom, Beam | D12: EVSCS20260709009 | F12: Voyage10 ml. | G12: {=IF(F12<>"",INDEX(tb_MainDatabase[Barcode],MATCH(F12,tb_MainDatabase[Link],0)),"")} -> 8857128012027 | H12: {=IF(F12<>"",INDEX(tb_MainDatabase[Grand],MATCH(F12,tb_MainDatabase[Link],0)),"")} -> EDP | I12: {=IF(F12<>"",INDEX(tb_MainDatabase[Size],MATCH(F12,tb_MainDatabase[Link],0)),"")} -> 10 ml. | J12: 1 | K12: {=IF(F12<>"",INDEX(tb_MainDatabase[ราคา],MATCH(F12,tb_MainDatabase[Link],0)),"")*J12} -> 450 | L12: 100 | M12: =K12-(L12*J12) -> 350 | N12: =SUMIF($D$3:D193,R12,$M$3:M193) -> 350 | O12: K Shop | P12: 46212 | Q12: 0.81805556 | R12: =IF(COUNTIF(D$3:D12, D12)>1, 0, D12) -> EVSCS20260709009 | T12: Thai
A13: Jul-26 | B13: 46212 | C13: Jom, Beam | D13: EVSCS20260709010 | F13: Nouveau10 ml. | G13: {=IF(F13<>"",INDEX(tb_MainDatabase[Barcode],MATCH(F13,tb_MainDatabase[Link],0)),"")} -> 8857128012170 | H13: {=IF(F13<>"",INDEX(tb_MainDatabase[Grand],MATCH(F13,tb_MainDatabase[Link],0)),"")} -> EDP | I13: {=IF(F13<>"",INDEX(tb_MainDatabase[Size],MATCH(F13,tb_MainDatabase[Link],0)),"")} -> 10 ml. | J13: 1 | K13: {=IF(F13<>"",INDEX(tb_MainDatabase[ราคา],MATCH(F13,tb_MainDatabase[Link],0)),"")*J13} -> 450 | L13: 100 | M13: =K13-(L13*J13) -> 350 | N13: =SUMIF($D$3:D194,R13,$M$3:M194) -> 350 | O13: K Shop | P13: 46212 | Q13: 0.82638889 | R13: =IF(COUNTIF(D$3:D13, D13)>1, 0, D13) -> EVSCS20260709010 | T13: Thai
A14: Jul-26 | B14: 46213 | C14: Jom, Beam | D14: EVSCS20260710001 | F14: Senorita10 ml. | G14: {=IF(F14<>"",INDEX(tb_MainDatabase[Barcode],MATCH(F14,tb_MainDatabase[Link],0)),"")} -> 8857128012039 | H14: {=IF(F14<>"",INDEX(tb_MainDatabase[Grand],MATCH(F14,tb_MainDatabase[Link],0)),"")} -> EDP | I14: {=IF(F14<>"",INDEX(tb_MainDatabase[Size],MATCH(F14,tb_MainDatabase[Link],0)),"")} -> 10 ml. | J14: 1 | K14: {=IF(F14<>"",INDEX(tb_MainDatabase[ราคา],MATCH(F14,tb_MainDatabase[Link],0)),"")*J14} -> 450 | L14: 100 | M14: =K14-(L14*J14) -> 350 | N14: =SUMIF($D$3:D195,R14,$M$3:M195) -> 350 | O14: K Shop | P14: 46213 | Q14: 0.54861111 | R14: =IF(COUNTIF(D$3:D14, D14)>1, 0, D14) -> EVSCS20260710001 | T14: Thai
A15: Jul-26 | B15: 46213 | C15: Jom, Beam | D15: EVSCS20260710002 | F15: Secret of Peach30 ml. | G15: {=IF(F15<>"",INDEX(tb_MainDatabase[Barcode],MATCH(F15,tb_MainDatabase[Link],0)),"")} -> 8857128011850 | H15: {=IF(F15<>"",INDEX(tb_MainDatabase[Grand],MATCH(F15,tb_MainDatabase[Link],0)),"")} -> EDP | I15: {=IF(F15<>"",INDEX(tb_MainDatabase[Size],MATCH(F15,tb_MainDatabase[Link],0)),"")} -> 30 ml. | J15: 1 | K15: {=IF(F15<>"",INDEX(tb_MainDatabase[ราคา],MATCH(F15,tb_MainDatabase[Link],0)),"")*J15} -> 1290 | L15: 300 | M15: =K15-(L15*J15) -> 990 | N15: =SUMIF($D$3:D196,R15,$M$3:M196) -> 990 | O15: K Shop | P15: 46213 | Q15: 0.54930556 | R15: =IF(COUNTIF(D$3:D15, D15)>1, 0, D15) -> EVSCS20260710002 | T15: Thai
A16: Jul-26 | B16: 46213 | C16: Jom, Beam | D16: EVSCS20260710003 | F16: Legend of Oud10 ml. | G16: {=IF(F16<>"",INDEX(tb_MainDatabase[Barcode],MATCH(F16,tb_MainDatabase[Link],0)),"")} -> 8857128012110 | H16: {=IF(F16<>"",INDEX(tb_MainDatabase[Grand],MATCH(F16,tb_MainDatabase[Link],0)),"")} -> EDP+ | I16: {=IF(F16<>"",INDEX(tb_MainDatabase[Size],MATCH(F16,tb_MainDatabase[Link],0)),"")} -> 10 ml. | J16: 1 | K16: {=IF(F16<>"",INDEX(tb_MainDatabase[ราคา],MATCH(F16,tb_MainDatabase[Link],0)),"")*J16} -> 650 | L16: 100 | M16: =K16-(L16*J16) -> 550 | N16: =SUMIF($D$3:D197,R16,$M$3:M197) -> 550 | O16: K Shop | P16: 46213 | Q16: 0.64791667 | R16: =IF(COUNTIF(D$3:D16, D16)>1, 0, D16) -> EVSCS20260710003 | T16: Thai
A17: Jul-26 | B17: 46213 | C17: Jom, Beam | D17: EVSCS20260710004 | F17: Passion30 ml. | G17: {=IF(F17<>"",INDEX(tb_MainDatabase[Barcode],MATCH(F17,tb_MainDatabase[Link],0)),"")} -> 8857128012156 | H17: {=IF(F17<>"",INDEX(tb_MainDatabase[Grand],MATCH(F17,tb_MainDatabase[Link],0)),"")} -> EDP | I17: {=IF(F17<>"",INDEX(tb_MainDatabase[Size],MATCH(F17,tb_MainDatabase[Link],0)),"")} -> 30 ml. | J17: 1 | K17: {=IF(F17<>"",INDEX(tb_MainDatabase[ราคา],MATCH(F17,tb_MainDatabase[Link],0)),"")*J17} -> 1290 | L17: 300 | M17: =K17-(L17*J17) -> 990 | N17: =SUMIF($D$3:D198,R17,$M$3:M198) -> 990 | O17: K Shop Credit Card | P17: 46213 | Q17: 0.73263889 | R17: =IF(COUNTIF(D$3:D17, D17)>1, 0, D17) -> EVSCS20260710004 | T17: Thai
A18: Jul-26 | B18: 46213 | C18: Jom, Beam | D18: EVSCS20260710005 | F18: Dream Island10 ml. | G18: {=IF(F18<>"",INDEX(tb_MainDatabase[Barcode],MATCH(F18,tb_MainDatabase[Link],0)),"")} -> 8857128012030 | H18: {=IF(F18<>"",INDEX(tb_MainDatabase[Grand],MATCH(F18,tb_MainDatabase[Link],0)),"")} -> EDP | I18: {=IF(F18<>"",INDEX(tb_MainDatabase[Size],MATCH(F18,tb_MainDatabase[Link],0)),"")} -> 10 ml. | J18: 1 | K18: {=IF(F18<>"",INDEX(tb_MainDatabase[ราคา],MATCH(F18,tb_MainDatabase[Link],0)),"")*J18} -> 450 | L18: 100 | M18: =K18-(L18*J18) -> 350 | N18: =SUMIF($D$3:D199,R18,$M$3:M199) -> 350 | O18: K Shop | P18: 46213 | Q18: 0.73819444 | R18: =IF(COUNTIF(D$3:D18, D18)>1, 0, D18) -> EVSCS20260710005 | T18: Thai
A19: Jul-26 | B19: 46213 | C19: Jom, Beam | D19: EVSCS20260710006 | F19: Rosarine10 ml. | G19: {=IF(F19<>"",INDEX(tb_MainDatabase[Barcode],MATCH(F19,tb_MainDatabase[Link],0)),"")} -> 8857128012160 | H19: {=IF(F19<>"",INDEX(tb_MainDatabase[Grand],MATCH(F19,tb_MainDatabase[Link],0)),"")} -> EDP | I19: {=IF(F19<>"",INDEX(tb_MainDatabase[Size],MATCH(F19,tb_MainDatabase[Link],0)),"")} -> 10 ml. | J19: 1 | K19: {=IF(F19<>"",INDEX(tb_MainDatabase[ราคา],MATCH(F19,tb_MainDatabase[Link],0)),"")*J19} -> 450 | L19: 100 | M19: =K19-(L19*J19) -> 350 | N19: =SUMIF($D$3:D200,R19,$M$3:M200) -> 350 | O19: K Shop | P19: 46213 | Q19: 0.82777778 | R19: =IF(COUNTIF(D$3:D19, D19)>1, 0, D19) -> EVSCS20260710006 | T19: Thai
A20: Jul-26 | B20: 46214 | C20: Aries, Chris | D20: EVSCS20260711001 | F20: Angel10 ml. | G20: {=IF(F20<>"",INDEX(tb_MainDatabase[Barcode],MATCH(F20,tb_MainDatabase[Link],0)),"")} -> 8857128012166 | H20: {=IF(F20<>"",INDEX(tb_MainDatabase[Grand],MATCH(F20,tb_MainDatabase[Link],0)),"")} -> EDP | I20: {=IF(F20<>"",INDEX(tb_MainDatabase[Size],MATCH(F20,tb_MainDatabase[Link],0)),"")} -> 10 ml. | J20: 1 | K20: {=IF(F20<>"",INDEX(tb_MainDatabase[ราคา],MATCH(F20,tb_MainDatabase[Link],0)),"")*J20} -> 450 | L20: 100 | M20: =K20-(L20*J20) -> 350 | N20: =SUMIF($D$3:D201,R20,$M$3:M201) -> 350 | O20: K Shop | P20: 46214 | Q20: 0.51041667 | R20: =IF(COUNTIF(D$3:D20, D20)>1, 0, D20) -> EVSCS20260711001 | T20: Thai
A21: Jul-26 | B21: 46214 | C21: Aries, Chris | D21: EVSCS20260711002 | F21: Angel10 ml. | G21: {=IF(F21<>"",INDEX(tb_MainDatabase[Barcode],MATCH(F21,tb_MainDatabase[Link],0)),"")} -> 8857128012166 | H21: {=IF(F21<>"",INDEX(tb_MainDatabase[Grand],MATCH(F21,tb_MainDatabase[Link],0)),"")} -> EDP | I21: {=IF(F21<>"",INDEX(tb_MainDatabase[Size],MATCH(F21,tb_MainDatabase[Link],0)),"")} -> 10 ml. | J21: 1 | K21: {=IF(F21<>"",INDEX(tb_MainDatabase[ราคา],MATCH(F21,tb_MainDatabase[Link],0)),"")*J21} -> 450 | L21: 100 | M21: =K21-(L21*J21) -> 350 | N21: =SUMIF($D$3:D202,R21,$M$3:M202) -> 350 | O21: K Shop | P21: 46214 | Q21: 0.58472222 | R21: =IF(COUNTIF(D$3:D21, D21)>1, 0, D21) -> EVSCS20260711002 | T21: Thai
A22: Jul-26 | B22: 46214 | C22: Aries, Chris | D22: EVSCS20260711003 | F22: Rosarine50 ml. | G22: {=IF(F22<>"",INDEX(tb_MainDatabase[Barcode],MATCH(F22,tb_MainDatabase[Link],0)),"")} -> 8857128011621 | H22: {=IF(F22<>"",INDEX(tb_MainDatabase[Grand],MATCH(F22,tb_MainDatabase[Link],0)),"")} -> EDP | I22: {=IF(F22<>"",INDEX(tb_MainDatabase[Size],MATCH(F22,tb_MainDatabase[Link],0)),"")} -> 50 ml. | J22: 1 | K22: {=IF(F22<>"",INDEX(tb_MainDatabase[ราคา],MATCH(F22,tb_MainDatabase[Link],0)),"")*J22} -> 1890 | L22: 400 | M22: =K22-(L22*J22) -> 1490 | N22: =SUMIF($D$3:D203,R22,$M$3:M203) -> 1490 | O22: K Shop | P22: 46214 | Q22: 0.62291667 | R22: =IF(COUNTIF(D$3:D22, D22)>1, 0, D22) -> EVSCS20260711003 | T22: Thai
A23: Jul-26 | B23: 46214 | C23: Aries, Chris | D23: EVSCS20260711004 | F23: Rosarine10 ml. | G23: {=IF(F23<>"",INDEX(tb_MainDatabase[Barcode],MATCH(F23,tb_MainDatabase[Link],0)),"")} -> 8857128012160 | H23: {=IF(F23<>"",INDEX(tb_MainDatabase[Grand],MATCH(F23,tb_MainDatabase[Link],0)),"")} -> EDP | I23: {=IF(F23<>"",INDEX(tb_MainDatabase[Size],MATCH(F23,tb_MainDatabase[Link],0)),"")} -> 10 ml. | J23: 1 | K23: {=IF(F23<>"",INDEX(tb_MainDatabase[ราคา],MATCH(F23,tb_MainDatabase[Link],0)),"")*J23} -> 450 | L23: 100 | M23: =K23-(L23*J23) -> 350 | N23: =SUMIF($D$3:D204,R23,$M$3:M204) -> 350 | O23: K Shop | P23: 46214 | Q23: 0.63402778 | R23: =IF(COUNTIF(D$3:D23, D23)>1, 0, D23) -> EVSCS20260711004 | T23: Thai
... A25: Jul-26 | B25: 46214 | C25: Aries, Chris | D25: EVSCS20260711006 | F25: Aqua10 ml. | G25: {=IF(F25<>"",INDEX(tb_MainDatabase[Barcode],MATCH(F25,tb_MainDatabase[Link],0)),"")} -> 8857128012026 | H25: {=IF(F25<>"",INDEX(tb_MainDatabase[Grand],MATCH(F25,tb_MainDatabase[Link],0)),"")} -> EDP | I25: {=IF(F25<>"",INDEX(tb_MainDatabase[Size],MATCH(F25,tb_MainDatabase[Link],0)),"")} -> 10 ml. | J25: 1 | K25: {=IF(F25<>"",INDEX(tb_MainDatabase[ราคา],MATCH(F25,tb_MainDatabase[Link],0)),"")*J25} -> 450 | L25: 100 | M25: =K25-(L25*J25) -> 350 | N25: =SUMIF($D$3:D206,R25,$M$3:M206) -> 700 | O25: K Shop | P25: 46214 | Q25: 0.64513889 | R25: =IF(COUNTIF(D$3:D25, D25)>1, 0, D25) -> EVSCS20260711006 | T25: Thai
A26: Jul-26 | B26: 46214 | C26: Aries, Chris | D26: EVSCS20260711006 | F26: La Belle10 ml. | G26: {=IF(F26<>"",INDEX(tb_MainDatabase[Barcode],MATCH(F26,tb_MainDatabase[Link],0)),"")} -> 8857128012034 | H26: {=IF(F26<>"",INDEX(tb_MainDatabase[Grand],MATCH(F26,tb_MainDatabase[Link],0)),"")} -> EDP | I26: {=IF(F26<>"",INDEX(tb_MainDatabase[Size],MATCH(F26,tb_MainDatabase[Link],0)),"")} -> 10 ml. | J26: 1 | K26: {=IF(F26<>"",INDEX(tb_MainDatabase[ราคา],MATCH(F26,tb_MainDatabase[Link],0)),"")*J26} -> 450 | L26: 100 | M26: =K26-(L26*J26) -> 350 | N26: =SUMIF($D$3:D207,R26,$M$3:M207) -> 0 | R26: =IF(COUNTIF(D$3:D26, D26)>1, 0, D26) -> 0
A27: Jul-26 | B27: 46214 | C27: Aries, Chris | D27: EVSCS20260711007 | F27: Aqua10 ml. | G27: {=IF(F27<>"",INDEX(tb_MainDatabase[Barcode],MATCH(F27,tb_MainDatabase[Link],0)),"")} -> 8857128012026 | H27: {=IF(F27<>"",INDEX(tb_MainDatabase[Grand],MATCH(F27,tb_MainDatabase[Link],0)),"")} -> EDP | I27: {=IF(F27<>"",INDEX(tb_MainDatabase[Size],MATCH(F27,tb_MainDatabase[Link],0)),"")} -> 10 ml. | J27: 1 | K27: {=IF(F27<>"",INDEX(tb_MainDatabase[ราคา],MATCH(F27,tb_MainDatabase[Link],0)),"")*J27} -> 450 | L27: 100 | M27: =K27-(L27*J27) -> 350 | N27: =SUMIF($D$3:D208,R27,$M$3:M208) -> 350 | O27: K Shop | P27: 46214 | Q27: 0.66180556 | R27: =IF(COUNTIF(D$3:D27, D27)>1, 0, D27) -> EVSCS20260711007 | T27: Thai
A28: Jul-26 | B28: 46214 | C28: Aries, Chris | D28: EVSCS20260711008 | F28: Aqua30 ml. | G28: {=IF(F28<>"",INDEX(tb_MainDatabase[Barcode],MATCH(F28,tb_MainDatabase[Link],0)),"")} -> 8857128012022 | H28: {=IF(F28<>"",INDEX(tb_MainDatabase[Grand],MATCH(F28,tb_MainDatabase[Link],0)),"")} -> EDP | I28: {=IF(F28<>"",INDEX(tb_MainDatabase[Size],MATCH(F28,tb_MainDatabase[Link],0)),"")} -> 30 ml. | J28: 1 | K28: {=IF(F28<>"",INDEX(tb_MainDatabase[ราคา],MATCH(F28,tb_MainDatabase[Link],0)),"")*J28} -> 1290 | L28: 300 | M28: =K28-(L28*J28) -> 990 | N28: =SUMIF($D$3:D209,R28,$M$3:M209) -> 990 | O28: K Shop Credit Card | P28: 46214 | Q28: 0.66805556 | R28: =IF(COUNTIF(D$3:D28, D28)>1, 0, D28) -> EVSCS20260711008 | T28: Thai
A29: Jul-26 | B29: 46214 | C29: Aries, Chris | D29: EVSCS20260711009 | F29: La Belle10 ml. | G29: {=IF(F29<>"",INDEX(tb_MainDatabase[Barcode],MATCH(F29,tb_MainDatabase[Link],0)),"")} -> 8857128012034 | H29: {=IF(F29<>"",INDEX(tb_MainDatabase[Grand],MATCH(F29,tb_MainDatabase[Link],0)),"")} -> EDP | I29: {=IF(F29<>"",INDEX(tb_MainDatabase[Size],MATCH(F29,tb_MainDatabase[Link],0)),"")} -> 10 ml. | J29: 1 | K29: {=IF(F29<>"",INDEX(tb_MainDatabase[ราคา],MATCH(F29,tb_MainDatabase[Link],0)),"")*J29} -> 450 | L29: 100 | M29: =K29-(L29*J29) -> 350 | N29: =SUMIF($D$3:D210,R29,$M$3:M210) -> 350 | O29: K Shop | P29: 46214 | Q29: 0.68194444 | R29: =IF(COUNTIF(D$3:D29, D29)>1, 0, D29) -> EVSCS20260711009 | T29: Thai
A30: Jul-26 | B30: 46214 | C30: Aries, Chris | D30: EVSCS20260711010 | F30: Rosarine10 ml. | G30: {=IF(F30<>"",INDEX(tb_MainDatabase[Barcode],MATCH(F30,tb_MainDatabase[Link],0)),"")} -> 8857128012160 | H30: {=IF(F30<>"",INDEX(tb_MainDatabase[Grand],MATCH(F30,tb_MainDatabase[Link],0)),"")} -> EDP | I30: {=IF(F30<>"",INDEX(tb_MainDatabase[Size],MATCH(F30,tb_MainDatabase[Link],0)),"")} -> 10 ml. | J30: 1 | K30: {=IF(F30<>"",INDEX(tb_MainDatabase[ราคา],MATCH(F30,tb_MainDatabase[Link],0)),"")*J30} -> 450 | L30: 100 | M30: =K30-(L30*J30) -> 350 | N30: =SUMIF($D$3:D211,R30,$M$3:M211) -> 350 | O30: K Shop | P30: 46214 | Q30: 0.68680556 | R30: =IF(COUNTIF(D$3:D30, D30)>1, 0, D30) -> EVSCS20260711010 | T30: Thai
A31: Jul-26 | B31: 46214 | C31: Aries, Chris | D31: EVSCS20260711011 | F31: Gambling34+3510 ml. | G31: {=IF(F31<>"",INDEX(tb_MainDatabase[Barcode],MATCH(F31,tb_MainDatabase[Link],0)),"")} -> 8857128012103 | H31: {=IF(F31<>"",INDEX(tb_MainDatabase[Grand],MATCH(F31,tb_MainDatabase[Link],0)),"")} -> PARFUM | I31: {=IF(F31<>"",INDEX(tb_MainDatabase[Size],MATCH(F31,tb_MainDatabase[Link],0)),"")} -> 10 ml. | J31: 1 | K31: {=IF(F31<>"",INDEX(tb_MainDatabase[ราคา],MATCH(F31,tb_MainDatabase[Link],0)),"")*J31} -> 850 | L31: 100 | M31: =K31-(L31*J31) -> 750 | N31: =SUMIF($D$3:D212,R31,$M$3:M212) -> 2140 | O31: K Shop | P31: 46214 | Q31: 0.67847222 | R31: =IF(COUNTIF(D$3:D31, D31)>1, 0, D31) -> EVSCS20260711011 | T31: Foreign
A32: Jul-26 | B32: 46214 | C32: Aries, Chris | D32: EVSCS20260711011 | F32: Blackest Black30 ml. | G32: {=IF(F32<>"",INDEX(tb_MainDatabase[Barcode],MATCH(F32,tb_MainDatabase[Link],0)),"")} -> 8857128012005 | H32: {=IF(F32<>"",INDEX(tb_MainDatabase[Grand],MATCH(F32,tb_MainDatabase[Link],0)),"")} -> EDP+ | I32: {=IF(F32<>"",INDEX(tb_MainDatabase[Size],MATCH(F32,tb_MainDatabase[Link],0)),"")} -> 30 ml. | J32: 1 | K32: {=IF(F32<>"",INDEX(tb_MainDatabase[ราคา],MATCH(F32,tb_MainDatabase[Link],0)),"")*J32} -> 1890 | L32: 500 | M32: =K32-(L32*J32) -> 1390 | N32: =SUMIF($D$3:D213,R32,$M$3:M213) -> 0 | R32: =IF(COUNTIF(D$3:D32, D32)>1, 0, D32) -> 0
A33: Jul-26 | B33: 46214 | C33: Aries, Chris | D33: EVSCS20260711012 | F33: Secret of Peach30 ml. | G33: {=IF(F33<>"",INDEX(tb_MainDatabase[Barcode],MATCH(F33,tb_MainDatabase[Link],0)),"")} -> 8857128011850 | H33: {=IF(F33<>"",INDEX(tb_MainDatabase[Grand],MATCH(F33,tb_MainDatabase[Link],0)),"")} -> EDP | I33: {=IF(F33<>"",INDEX(tb_MainDatabase[Size],MATCH(F33,tb_MainDatabase[Link],0)),"")} -> 30 ml. | J33: 1 | K33: {=IF(F33<>"",INDEX(tb_MainDatabase[ราคา],MATCH(F33,tb_MainDatabase[Link],0)),"")*J33} -> 1290 | L33: 300 | M33: =K33-(L33*J33) -> 990 | N33: =SUMIF($D$3:D214,R33,$M$3:M214) -> 990 | O33: K Shop | P33: 46214 | Q33: 0.70902778 | R33: =IF(COUNTIF(D$3:D33, D33)>1, 0, D33) -> EVSCS20260711012 | T33: Thai
A34: Jul-26 | B34: 46214 | C34: Aries, Chris | D34: EVSCS20260711013 | F34: Sparkling Mandarin10 ml. | G34: {=IF(F34<>"",INDEX(tb_MainDatabase[Barcode],MATCH(F34,tb_MainDatabase[Link],0)),"")} -> 8857128012108 | H34: {=IF(F34<>"",INDEX(tb_MainDatabase[Grand],MATCH(F34,tb_MainDatabase[Link],0)),"")} -> EDP+ | I34: {=IF(F34<>"",INDEX(tb_MainDatabase[Size],MATCH(F34,tb_MainDatabase[Link],0)),"")} -> 10 ml. | J34: 1 | K34: {=IF(F34<>"",INDEX(tb_MainDatabase[ราคา],MATCH(F34,tb_MainDatabase[Link],0)),"")*J34} -> 650 | L34: 100 | M34: =K34-(L34*J34) -> 550 | N34: =SUMIF($D$3:D215,R34,$M$3:M215) -> 550 | O34: K Shop | P34: 46214 | Q34: 0.71944444 | R34: =IF(COUNTIF(D$3:D34, D34)>1, 0, D34) -> EVSCS20260711013 | T34: Thai
A35: Jul-26 | B35: 46214 | C35: Aries, Chris | D35: EVSCS20260711014 | F35: Rosarine50 ml. | G35: {=IF(F35<>"",INDEX(tb_MainDatabase[Barcode],MATCH(F35,tb_MainDatabase[Link],0)),"")} -> 8857128011621 | H35: {=IF(F35<>"",INDEX(tb_MainDatabase[Grand],MATCH(F35,tb_MainDatabase[Link],0)),"")} -> EDP | I35: {=IF(F35<>"",INDEX(tb_MainDatabase[Size],MATCH(F35,tb_MainDatabase[Link],0)),"")} -> 50 ml. | J35: 1 | K35: {=IF(F35<>"",INDEX(tb_MainDatabase[ราคา],MATCH(F35,tb_MainDatabase[Link],0)),"")*J35} -> 1890 | L35: 400 | M35: =K35-(L35*J35) -> 1490 | N35: =SUMIF($D$3:D216,R35,$M$3:M216) -> 2980 | O35: K Shop | P35: 46214 | Q35: 0.73333333 | R35: =IF(COUNTIF(D$3:D35, D35)>1, 0, D35) -> EVSCS20260711014 | T35: Thai
A36: Jul-26 | B36: 46214 | C36: Aries, Chris | D36: EVSCS20260711014 | F36: La Belle50 ml. | G36: {=IF(F36<>"",INDEX(tb_MainDatabase[Barcode],MATCH(F36,tb_MainDatabase[Link],0)),"")} -> 8857128011058 | H36: {=IF(F36<>"",INDEX(tb_MainDatabase[Grand],MATCH(F36,tb_MainDatabase[Link],0)),"")} -> EDP | I36: {=IF(F36<>"",INDEX(tb_MainDatabase[Size],MATCH(F36,tb_MainDatabase[Link],0)),"")} -> 50 ml. | J36: 1 | K36: {=IF(F36<>"",INDEX(tb_MainDatabase[ราคา],MATCH(F36,tb_MainDatabase[Link],0)),"")*J36} -> 1890 | L36: 400 | M36: =K36-(L36*J36) -> 1490 | N36: =SUMIF($D$3:D217,R36,$M$3:M217) -> 0 | R36: =IF(COUNTIF(D$3:D36, D36)>1, 0, D36) -> 0
A37: Jul-26 | B37: 46214 | C37: Aries, Chris | D37: EVSCS20260711015 | F37: Dream Island10 ml. | G37: {=IF(F37<>"",INDEX(tb_MainDatabase[Barcode],MATCH(F37,tb_MainDatabase[Link],0)),"")} -> 8857128012030 | H37: {=IF(F37<>"",INDEX(tb_MainDatabase[Grand],MATCH(F37,tb_MainDatabase[Link],0)),"")} -> EDP | I37: {=IF(F37<>"",INDEX(tb_MainDatabase[Size],MATCH(F37,tb_MainDatabase[Link],0)),"")} -> 10 ml. | J37: 1 | K37: {=IF(F37<>"",INDEX(tb_MainDatabase[ราคา],MATCH(F37,tb_MainDatabase[Link],0)),"")*J37} -> 450 | L37: 100 | M37: =K37-(L37*J37) -> 350 | N37: =SUMIF($D$3:D218,R37,$M$3:M218) -> 350 | O37: K Shop | P37: 46214 | Q37: 0.77569444 | R37: =IF(COUNTIF(D$3:D37, D37)>1, 0, D37) -> EVSCS20260711015 | T37: Thai
A38: Jul-26 | B38: 46214 | C38: Aries, Chris | D38: EVSCS20260711016 | F38: Never Blue50 ml. | G38: {=IF(F38<>"",INDEX(tb_MainDatabase[Barcode],MATCH(F38,tb_MainDatabase[Link],0)),"")} -> 8857128011287 | H38: {=IF(F38<>"",INDEX(tb_MainDatabase[Grand],MATCH(F38,tb_MainDatabase[Link],0)),"")} -> EDP | I38: {=IF(F38<>"",INDEX(tb_MainDatabase[Size],MATCH(F38,tb_MainDatabase[Link],0)),"")} -> 50 ml. | J38: 1 | K38: {=IF(F38<>"",INDEX(tb_MainDatabase[ราคา],MATCH(F38,tb_MainDatabase[Link],0)),"")*J38} -> 1890 | L38: 400 | M38: =K38-(L38*J38) -> 1490 | N38: =SUMIF($D$3:D219,R38,$M$3:M219) -> 2190 | O38: K Shop | P38: 46214 | Q38: 0.76944444 | R38: =IF(COUNTIF(D$3:D38, D38)>1, 0, D38) -> EVSCS20260711016 | T38: Thai
A39: Jul-26 | B39: 46214 | C39: Aries, Chris | D39: EVSCS20260711016 | F39: Zeus10 ml. | G39: {=IF(F39<>"",INDEX(tb_MainDatabase[Barcode],MATCH(F39,tb_MainDatabase[Link],0)),"")} -> 8857128012041 | H39: {=IF(F39<>"",INDEX(tb_MainDatabase[Grand],MATCH(F39,tb_MainDatabase[Link],0)),"")} -> EDP | I39: {=IF(F39<>"",INDEX(tb_MainDatabase[Size],MATCH(F39,tb_MainDatabase[Link],0)),"")} -> 10 ml. | J39: 1 | K39: {=IF(F39<>"",INDEX(tb_MainDatabase[ราคา],MATCH(F39,tb_MainDatabase[Link],0)),"")*J39} -> 450 | L39: 100 | M39: =K39-(L39*J39) -> 350 | N39: =SUMIF($D$3:D220,R39,$M$3:M220) -> 0 | R39: =IF(COUNTIF(D$3:D39, D39)>1, 0, D39) -> 0
A40: Jul-26 | B40: 46214 | C40: Aries, Chris | D40: EVSCS20260711016 | F40: Passion10 ml. | G40: {=IF(F40<>"",INDEX(tb_MainDatabase[Barcode],MATCH(F40,tb_MainDatabase[Link],0)),"")} -> 8857128012157 | H40: {=IF(F40<>"",INDEX(tb_MainDatabase[Grand],MATCH(F40,tb_MainDatabase[Link],0)),"")} -> EDP | I40: {=IF(F40<>"",INDEX(tb_MainDatabase[Size],MATCH(F40,tb_MainDatabase[Link],0)),"")} -> 10 ml. | J40: 1 | K40: {=IF(F40<>"",INDEX(tb_MainDatabase[ราคา],MATCH(F40,tb_MainDatabase[Link],0)),"")*J40} -> 450 | L40: 100 | M40: =K40-(L40*J40) -> 350 | N40: =SUMIF($D$3:D221,R40,$M$3:M221) -> 0 | R40: =IF(COUNTIF(D$3:D40, D40)>1, 0, D40) -> 0
A41: Jul-26 | B41: 46214 | C41: Aries, Chris | D41: EVSCS20260711017 | F41: Rosarine30 ml. | G41: {=IF(F41<>"",INDEX(tb_MainDatabase[Barcode],MATCH(F41,tb_MainDatabase[Link],0)),"")} -> 8857128012159 | H41: {=IF(F41<>"",INDEX(tb_MainDatabase[Grand],MATCH(F41,tb_MainDatabase[Link],0)),"")} -> EDP | I41: {=IF(F41<>"",INDEX(tb_MainDatabase[Size],MATCH(F41,tb_MainDatabase[Link],0)),"")} -> 30 ml. | J41: 1 | K41: {=IF(F41<>"",INDEX(tb_MainDatabase[ราคา],MATCH(F41,tb_MainDatabase[Link],0)),"")*J41} -> 1290 | L41: 300 | M41: =K41-(L41*J41) -> 990 | N41: =SUMIF($D$3:D222,R41,$M$3:M222) -> 990 | O41: K Shop | P41: 46214 | Q41: 0.78541667 | R41: =IF(COUNTIF(D$3:D41, D41)>1, 0, D41) -> EVSCS20260711017 | T41: Thai
...

Sheet PO List Lab Parfumo
B1: *** | C1: *** | D1: *** | E1: *** | G1: *** | J1: *** | K1: ***
A3: Order | B3: Date | C3: PO Order Number | D3: PO Order Version | E3: Branch | F3: Branches | G3: Barcode | H3: Scent | I3: Size | J3: จำนวน | K3: Delivery Number | L3: Phone | M3: Shipping Name | N3: Address | O3: Remark
A4: =IF(C4="","",ROW()-ROW(tb_PO[[#HEADERS],[Order]])) -> 1 | B4: 45981 | C4: WPO251120001 | D4: WPO251120001-2 | E4: 01_CTW - Central World | F4: {=IF(E4<>"",INDEX(tb_Address[Branch],MATCH(E4,tb_Address[Branch Code],0)),"")} -> สาขาที่ 00001 | G4: 8857128011188 | H4: {=IF(G4<>"",INDEX(tb_MainDatabase[Scent],MATCH(G4,tb_MainDatabase[Barcode],0)),"")} -> 1000 Thousand | I4: {=IF(G4<>"",INDEX(tb_MainDatabase[Size],MATCH(G4,tb_MainDatabase[Barcode],0)),"")} -> 50 ml. | J4: 5 | L4: {=IFERROR(IF(C4=C3,IF(C4="","","-"),INDEX(tb_Address[Store Tel.],MATCH(F4,tb_Address[Branch],0))),"")} -> - | M4: {=IFERROR(IF(C4=C3,IF(C4="","","-"),INDEX(tb_Address[ชื่อผู้รับสินค้า],MATCH(F4,tb_Address[Branch],0))),"")} -> - | N4: {=IFERROR(IF(C4=C3,IF(C4="","","-"),INDEX(tb_Address[ที่อยู่ Store],MATCH(F4,tb_Address[Branch],0))),"")} -> -
A5: =IF(C5="","",ROW()-ROW(tb_PO[[#HEADERS],[Order]])) -> 2 | B5: 45981 | C5: WPO251120001 | D5: WPO251120001-2 | E5: 01_CTW - Central World | F5: {=IF(E5<>"",INDEX(tb_Address[Branch],MATCH(E5,tb_Address[Branch Code],0)),"")} -> สาขาที่ 00001 | G5: 8857128011669 | H5: {=IF(G5<>"",INDEX(tb_MainDatabase[Scent],MATCH(G5,tb_MainDatabase[Barcode],0)),"")} -> Blackest Black | I5: {=IF(G5<>"",INDEX(tb_MainDatabase[Size],MATCH(G5,tb_MainDatabase[Barcode],0)),"")} -> 50 ml. | J5: 2 | L5: {=IFERROR(IF(C5=C4,IF(C5="","","-"),INDEX(tb_Address[Store Tel.],MATCH(F5,tb_Address[Branch],0))),"")} -> - | M5: {=IFERROR(IF(C5=C4,IF(C5="","","-"),INDEX(tb_Address[ชื่อผู้รับสินค้า],MATCH(F5,tb_Address[Branch],0))),"")} -> - | N5: {=IFERROR(IF(C5=C4,IF(C5="","","-"),INDEX(tb_Address[ที่อยู่ Store],MATCH(F5,tb_Address[Branch],0))),"")} -> -
A6: =IF(C6="","",ROW()-ROW(tb_PO[[#HEADERS],[Order]])) -> 3 | B6: 45981 | C6: WPO251120001 | D6: WPO251120001-2 | E6: 01_CTW - Central World | F6: {=IF(E6<>"",INDEX(tb_Address[Branch],MATCH(E6,tb_Address[Branch Code],0)),"")} -> สาขาที่ 00001 | G6: 8857128011225 | H6: {=IF(G6<>"",INDEX(tb_MainDatabase[Scent],MATCH(G6,tb_MainDatabase[Barcode],0)),"")} -> Blind Magnolia | I6: {=IF(G6<>"",INDEX(tb_MainDatabase[Size],MATCH(G6,tb_MainDatabase[Barcode],0)),"")} -> 50 ml. | J6: 5 | L6: {=IFERROR(IF(C6=C5,IF(C6="","","-"),INDEX(tb_Address[Store Tel.],MATCH(F6,tb_Address[Branch],0))),"")} -> - | M6: {=IFERROR(IF(C6=C5,IF(C6="","","-"),INDEX(tb_Address[ชื่อผู้รับสินค้า],MATCH(F6,tb_Address[Branch],0))),"")} -> - | N6: {=IFERROR(IF(C6=C5,IF(C6="","","-"),INDEX(tb_Address[ที่อยู่ Store],MATCH(F6,tb_Address[Branch],0))),"")} -> -
A7: =IF(C7="","",ROW()-ROW(tb_PO[[#HEADERS],[Order]])) -> 4 | B7: 45981 | C7: WPO251120001 | D7: WPO251120001-2 | E7: 01_CTW - Central World | F7: {=IF(E7<>"",INDEX(tb_Address[Branch],MATCH(E7,tb_Address[Branch Code],0)),"")} -> สาขาที่ 00001 | G7: 8857128012021 | H7: {=IF(G7<>"",INDEX(tb_MainDatabase[Scent],MATCH(G7,tb_MainDatabase[Barcode],0)),"")} -> Buoyant | I7: {=IF(G7<>"",INDEX(tb_MainDatabase[Size],MATCH(G7,tb_MainDatabase[Barcode],0)),"")} -> 50 ml. | J7: 5 | L7: {=IFERROR(IF(C7=C6,IF(C7="","","-"),INDEX(tb_Address[Store Tel.],MATCH(F7,tb_Address[Branch],0))),"")} -> - | M7: {=IFERROR(IF(C7=C6,IF(C7="","","-"),INDEX(tb_Address[ชื่อผู้รับสินค้า],MATCH(F7,tb_Address[Branch],0))),"")} -> - | N7: {=IFERROR(IF(C7=C6,IF(C7="","","-"),INDEX(tb_Address[ที่อยู่ Store],MATCH(F7,tb_Address[Branch],0))),"")} -> -
A8: =IF(C8="","",ROW()-ROW(tb_PO[[#HEADERS],[Order]])) -> 5 | B8: 45981 | C8: WPO251120001 | D8: WPO251120001-2 | E8: 01_CTW - Central World | F8: {=IF(E8<>"",INDEX(tb_Address[Branch],MATCH(E8,tb_Address[Branch Code],0)),"")} -> สาขาที่ 00001 | G8: 8857128011331 | H8: {=IF(G8<>"",INDEX(tb_MainDatabase[Scent],MATCH(G8,tb_MainDatabase[Barcode],0)),"")} -> Dionysus X | I8: {=IF(G8<>"",INDEX(tb_MainDatabase[Size],MATCH(G8,tb_MainDatabase[Barcode],0)),"")} -> 50 ml. | J8: 5 | L8: {=IFERROR(IF(C8=C7,IF(C8="","","-"),INDEX(tb_Address[Store Tel.],MATCH(F8,tb_Address[Branch],0))),"")} -> - | M8: {=IFERROR(IF(C8=C7,IF(C8="","","-"),INDEX(tb_Address[ชื่อผู้รับสินค้า],MATCH(F8,tb_Address[Branch],0))),"")} -> - | N8: {=IFERROR(IF(C8=C7,IF(C8="","","-"),INDEX(tb_Address[ที่อยู่ Store],MATCH(F8,tb_Address[Branch],0))),"")} -> -
A9: =IF(C9="","",ROW()-ROW(tb_PO[[#HEADERS],[Order]])) -> 6 | B9: 45981 | C9: WPO251120001 | D9: WPO251120001-2 | E9: 01_CTW - Central World | F9: {=IF(E9<>"",INDEX(tb_Address[Branch],MATCH(E9,tb_Address[Branch Code],0)),"")} -> สาขาที่ 00001 | G9: 8857128011300 | H9: {=IF(G9<>"",INDEX(tb_MainDatabase[Scent],MATCH(G9,tb_MainDatabase[Barcode],0)),"")} -> Dream Island | I9: {=IF(G9<>"",INDEX(tb_MainDatabase[Size],MATCH(G9,tb_MainDatabase[Barcode],0)),"")} -> 50 ml. | J9: 20 | L9: {=IFERROR(IF(C9=C8,IF(C9="","","-"),INDEX(tb_Address[Store Tel.],MATCH(F9,tb_Address[Branch],0))),"")} -> - | M9: {=IFERROR(IF(C9=C8,IF(C9="","","-"),INDEX(tb_Address[ชื่อผู้รับสินค้า],MATCH(F9,tb_Address[Branch],0))),"")} -> - | N9: {=IFERROR(IF(C9=C8,IF(C9="","","-"),INDEX(tb_Address[ที่อยู่ Store],MATCH(F9,tb_Address[Branch],0))),"")} -> -
A10: =IF(C10="","",ROW()-ROW(tb_PO[[#HEADERS],[Order]])) -> 7 | B10: 45981 | C10: WPO251120001 | D10: WPO251120001-2 | E10: 01_CTW - Central World | F10: {=IF(E10<>"",INDEX(tb_Address[Branch],MATCH(E10,tb_Address[Branch Code],0)),"")} -> สาขาที่ 00001 | G10: 8857128011317 | H10: {=IF(G10<>"",INDEX(tb_MainDatabase[Scent],MATCH(G10,tb_MainDatabase[Barcode],0)),"")} -> Eden | I10: {=IF(G10<>"",INDEX(tb_MainDatabase[Size],MATCH(G10,tb_MainDatabase[Barcode],0)),"")} -> 50 ml. | J10: 10 | L10: {=IFERROR(IF(C10=C9,IF(C10="","","-"),INDEX(tb_Address[Store Tel.],MATCH(F10,tb_Address[Branch],0))),"")} -> - | M10: {=IFERROR(IF(C10=C9,IF(C10="","","-"),INDEX(tb_Address[ชื่อผู้รับสินค้า],MATCH(F10,tb_Address[Branch],0))),"")} -> - | N10: {=IFERROR(IF(C10=C9,IF(C10="","","-"),INDEX(tb_Address[ที่อยู่ Store],MATCH(F10,tb_Address[Branch],0))),"")} -> -
A11: =IF(C11="","",ROW()-ROW(tb_PO[[#HEADERS],[Order]])) -> 8 | B11: 45981 | C11: WPO251120001 | D11: WPO251120001-2 | E11: 01_CTW - Central World | F11: {=IF(E11<>"",INDEX(tb_Address[Branch],MATCH(E11,tb_Address[Branch Code],0)),"")} -> สาขาที่ 00001 | G11: 8857128011133 | H11: {=IF(G11<>"",INDEX(tb_MainDatabase[Scent],MATCH(G11,tb_MainDatabase[Barcode],0)),"")} -> Excalibur (EDP) | I11: {=IF(G11<>"",INDEX(tb_MainDatabase[Size],MATCH(G11,tb_MainDatabase[Barcode],0)),"")} -> 50 ml. | J11: 5 | L11: {=IFERROR(IF(C11=C10,IF(C11="","","-"),INDEX(tb_Address[Store Tel.],MATCH(F11,tb_Address[Branch],0))),"")} -> - | M11: {=IFERROR(IF(C11=C10,IF(C11="","","-"),INDEX(tb_Address[ชื่อผู้รับสินค้า],MATCH(F11,tb_Address[Branch],0))),"")} -> - | N11: {=IFERROR(IF(C11=C10,IF(C11="","","-"),INDEX(tb_Address[ที่อยู่ Store],MATCH(F11,tb_Address[Branch],0))),"")} -> -
